[2023-11-29 14:07:54,505] {taskinstance.py:1159} INFO - Dependencies all met for <TaskInstance: d_1_etl_FinalProject.insert_province_daily scheduled__2023-11-28T00:00:00+00:00 [queued]>
[2023-11-29 14:07:54,516] {taskinstance.py:1159} INFO - Dependencies all met for <TaskInstance: d_1_etl_FinalProject.insert_province_daily scheduled__2023-11-28T00:00:00+00:00 [queued]>
[2023-11-29 14:07:54,517] {taskinstance.py:1356} INFO - 
--------------------------------------------------------------------------------
[2023-11-29 14:07:54,518] {taskinstance.py:1357} INFO - Starting attempt 6 of 6
[2023-11-29 14:07:54,518] {taskinstance.py:1358} INFO - 
--------------------------------------------------------------------------------
[2023-11-29 14:07:54,535] {taskinstance.py:1377} INFO - Executing <Task(PythonOperator): insert_province_daily> on 2023-11-28 00:00:00+00:00
[2023-11-29 14:07:54,591] {standard_task_runner.py:52} INFO - Started process 4201 to run task
[2023-11-29 14:07:54,594] {standard_task_runner.py:79} INFO - Running: ['***', 'tasks', 'run', 'd_1_etl_FinalProject', 'insert_province_daily', 'scheduled__2023-11-28T00:00:00+00:00', '--job-id', '96', '--raw', '--subdir', 'DAGS_FOLDER/d_1_etl_FinalProject.py', '--cfg-path', '/tmp/tmp790sul0i', '--error-file', '/tmp/tmpcf5mh_s3']
[2023-11-29 14:07:54,595] {standard_task_runner.py:80} INFO - Job 96: Subtask insert_province_daily
[2023-11-29 14:07:54,767] {task_command.py:369} INFO - Running <TaskInstance: d_1_etl_FinalProject.insert_province_daily scheduled__2023-11-28T00:00:00+00:00 [running]> on host 92ab6769debf
[2023-11-29 14:07:54,922] {taskinstance.py:1571} INFO - Exporting the following env vars:
AIRFLOW_CTX_DAG_OWNER=***
AIRFLOW_CTX_DAG_ID=d_1_etl_FinalProject
AIRFLOW_CTX_TASK_ID=insert_province_daily
AIRFLOW_CTX_EXECUTION_DATE=2023-11-28T00:00:00+00:00
AIRFLOW_CTX_TRY_NUMBER=6
AIRFLOW_CTX_DAG_RUN_ID=scheduled__2023-11-28T00:00:00+00:00
[2023-11-29 14:07:54,941] {base.py:68} INFO - Using connection ID 'Postgres' for task execution.
[2023-11-29 14:07:54,989] {base.py:68} INFO - Using connection ID 'Mysql' for task execution.
[2023-11-29 14:07:55,331] {taskinstance.py:1889} ERROR - Task failed with exception
Traceback (most recent call last):
  File "/home/airflow/.local/lib/python3.7/site-packages/airflow/operators/python.py", line 171, in execute
    return_value = self.execute_callable()
  File "/home/airflow/.local/lib/python3.7/site-packages/airflow/operators/python.py", line 189, in execute_callable
    return self.python_callable(*self.op_args, **self.op_kwargs)
  File "/opt/airflow/dags/d_1_etl_FinalProject.py", line 19, in insert_province_daily_func
    insert_province_daily_script.insert_province_daily(**kwargs)
  File "/opt/airflow/dags/modules/insert_province_daily_script.py", line 25, in insert_province_daily
    cursor_postgres.execute(query_dim_case)
psycopg2.errors.UndefinedTable: relation "dim_case" does not exist
LINE 1: SELECT id, status FROM dim_case
                               ^

[2023-11-29 14:07:55,360] {taskinstance.py:1400} INFO - Marking task as FAILED. dag_id=d_1_etl_FinalProject, task_id=insert_province_daily, execution_date=20231128T000000, start_date=20231129T140754, end_date=20231129T140755
[2023-11-29 14:07:55,379] {standard_task_runner.py:97} ERROR - Failed to execute job 96 for task insert_province_daily (relation "dim_case" does not exist
LINE 1: SELECT id, status FROM dim_case
                               ^
; 4201)
[2023-11-29 14:07:55,411] {local_task_job.py:156} INFO - Task exited with return code 1
[2023-11-29 14:07:55,448] {local_task_job.py:273} INFO - 0 downstream tasks scheduled from follow-on schedule check
