[2023-11-29 14:00:17,061] {taskinstance.py:1159} INFO - Dependencies all met for <TaskInstance: d_1_etl_FinalProject.insert_province_daily scheduled__2023-11-28T00:00:00+00:00 [queued]>
[2023-11-29 14:00:17,070] {taskinstance.py:1159} INFO - Dependencies all met for <TaskInstance: d_1_etl_FinalProject.insert_province_daily scheduled__2023-11-28T00:00:00+00:00 [queued]>
[2023-11-29 14:00:17,071] {taskinstance.py:1356} INFO - 
--------------------------------------------------------------------------------
[2023-11-29 14:00:17,072] {taskinstance.py:1357} INFO - Starting attempt 5 of 5
[2023-11-29 14:00:17,073] {taskinstance.py:1358} INFO - 
--------------------------------------------------------------------------------
[2023-11-29 14:00:17,089] {taskinstance.py:1377} INFO - Executing <Task(PythonOperator): insert_province_daily> on 2023-11-28 00:00:00+00:00
[2023-11-29 14:00:17,099] {standard_task_runner.py:79} INFO - Running: ['***', 'tasks', 'run', 'd_1_etl_FinalProject', 'insert_province_daily', 'scheduled__2023-11-28T00:00:00+00:00', '--job-id', '95', '--raw', '--subdir', 'DAGS_FOLDER/d_1_etl_FinalProject.py', '--cfg-path', '/tmp/tmphrja_f5y', '--error-file', '/tmp/tmp7dlu1k79']
[2023-11-29 14:00:17,097] {standard_task_runner.py:52} INFO - Started process 4039 to run task
[2023-11-29 14:00:17,102] {standard_task_runner.py:80} INFO - Job 95: Subtask insert_province_daily
[2023-11-29 14:00:17,190] {task_command.py:369} INFO - Running <TaskInstance: d_1_etl_FinalProject.insert_province_daily scheduled__2023-11-28T00:00:00+00:00 [running]> on host 92ab6769debf
[2023-11-29 14:00:17,288] {taskinstance.py:1571} INFO - Exporting the following env vars:
AIRFLOW_CTX_DAG_OWNER=***
AIRFLOW_CTX_DAG_ID=d_1_etl_FinalProject
AIRFLOW_CTX_TASK_ID=insert_province_daily
AIRFLOW_CTX_EXECUTION_DATE=2023-11-28T00:00:00+00:00
AIRFLOW_CTX_TRY_NUMBER=5
AIRFLOW_CTX_DAG_RUN_ID=scheduled__2023-11-28T00:00:00+00:00
[2023-11-29 14:00:17,301] {base.py:68} INFO - Using connection ID 'Postgres' for task execution.
[2023-11-29 14:00:17,324] {base.py:68} INFO - Using connection ID 'Mysql' for task execution.
[2023-11-29 14:00:17,376] {taskinstance.py:1889} ERROR - Task failed with exception
Traceback (most recent call last):
  File "/home/airflow/.local/lib/python3.7/site-packages/airflow/operators/python.py", line 171, in execute
    return_value = self.execute_callable()
  File "/home/airflow/.local/lib/python3.7/site-packages/airflow/operators/python.py", line 189, in execute_callable
    return self.python_callable(*self.op_args, **self.op_kwargs)
  File "/opt/airflow/dags/d_1_etl_FinalProject.py", line 19, in insert_province_daily_func
    insert_province_daily_script.insert_province_daily(**kwargs)
  File "/opt/airflow/dags/modules/insert_province_daily_script.py", line 25, in insert_province_daily
    cursor_postgres.execute(query_dim_case)
psycopg2.errors.UndefinedTable: relation "dim_case" does not exist
LINE 1: SELECT id, status_name FROM dim_case
                                    ^

[2023-11-29 14:00:17,394] {taskinstance.py:1400} INFO - Marking task as FAILED. dag_id=d_1_etl_FinalProject, task_id=insert_province_daily, execution_date=20231128T000000, start_date=20231129T140017, end_date=20231129T140017
[2023-11-29 14:00:17,409] {standard_task_runner.py:97} ERROR - Failed to execute job 95 for task insert_province_daily (relation "dim_case" does not exist
LINE 1: SELECT id, status_name FROM dim_case
                                    ^
; 4039)
[2023-11-29 14:00:17,439] {local_task_job.py:156} INFO - Task exited with return code 1
[2023-11-29 14:00:17,469] {local_task_job.py:273} INFO - 0 downstream tasks scheduled from follow-on schedule check
