[2023-11-27 14:13:11,692] {taskinstance.py:1159} INFO - Dependencies all met for <TaskInstance: d_1_etl_FinalProject.get_data_from_api scheduled__2023-11-26T00:00:00+00:00 [queued]>
[2023-11-27 14:13:11,704] {taskinstance.py:1159} INFO - Dependencies all met for <TaskInstance: d_1_etl_FinalProject.get_data_from_api scheduled__2023-11-26T00:00:00+00:00 [queued]>
[2023-11-27 14:13:11,705] {taskinstance.py:1356} INFO - 
--------------------------------------------------------------------------------
[2023-11-27 14:13:11,706] {taskinstance.py:1357} INFO - Starting attempt 1 of 1
[2023-11-27 14:13:11,706] {taskinstance.py:1358} INFO - 
--------------------------------------------------------------------------------
[2023-11-27 14:13:11,723] {taskinstance.py:1377} INFO - Executing <Task(PythonOperator): get_data_from_api> on 2023-11-26 00:00:00+00:00
[2023-11-27 14:13:11,737] {standard_task_runner.py:52} INFO - Started process 2437 to run task
[2023-11-27 14:13:11,746] {standard_task_runner.py:79} INFO - Running: ['***', 'tasks', 'run', 'd_1_etl_FinalProject', 'get_data_from_api', 'scheduled__2023-11-26T00:00:00+00:00', '--job-id', '52', '--raw', '--subdir', 'DAGS_FOLDER/d_1_etl_FinalProject.py', '--cfg-path', '/tmp/tmpmgus3bby', '--error-file', '/tmp/tmp_89dx1sj']
[2023-11-27 14:13:11,747] {standard_task_runner.py:80} INFO - Job 52: Subtask get_data_from_api
[2023-11-27 14:13:11,823] {task_command.py:369} INFO - Running <TaskInstance: d_1_etl_FinalProject.get_data_from_api scheduled__2023-11-26T00:00:00+00:00 [running]> on host 92ab6769debf
[2023-11-27 14:13:12,365] {taskinstance.py:1571} INFO - Exporting the following env vars:
AIRFLOW_CTX_DAG_OWNER=***
AIRFLOW_CTX_DAG_ID=d_1_etl_FinalProject
AIRFLOW_CTX_TASK_ID=get_data_from_api
AIRFLOW_CTX_EXECUTION_DATE=2023-11-26T00:00:00+00:00
AIRFLOW_CTX_TRY_NUMBER=1
AIRFLOW_CTX_DAG_RUN_ID=scheduled__2023-11-26T00:00:00+00:00
[2023-11-27 14:13:12,367] {taskinstance.py:1889} ERROR - Task failed with exception
Traceback (most recent call last):
  File "/home/airflow/.local/lib/python3.7/site-packages/airflow/operators/python.py", line 171, in execute
    return_value = self.execute_callable()
  File "/home/airflow/.local/lib/python3.7/site-packages/airflow/operators/python.py", line 189, in execute_callable
    return self.python_callable(*self.op_args, **self.op_kwargs)
  File "/opt/airflow/dags/d_1_etl_FinalProject.py", line 12, in get_data_from_api_func
    get_data_from_api_script.get_data_from_api_func()
AttributeError: module 'modules.get_data_from_api_script' has no attribute 'get_data_from_api_func'
[2023-11-27 14:13:12,391] {taskinstance.py:1400} INFO - Marking task as FAILED. dag_id=d_1_etl_FinalProject, task_id=get_data_from_api, execution_date=20231126T000000, start_date=20231127T141311, end_date=20231127T141312
[2023-11-27 14:13:12,415] {standard_task_runner.py:97} ERROR - Failed to execute job 52 for task get_data_from_api (module 'modules.get_data_from_api_script' has no attribute 'get_data_from_api_func'; 2437)
[2023-11-27 14:13:12,435] {local_task_job.py:156} INFO - Task exited with return code 1
[2023-11-27 14:13:12,484] {local_task_job.py:273} INFO - 0 downstream tasks scheduled from follow-on schedule check
