[2023-11-27 14:22:21,347] {taskinstance.py:1159} INFO - Dependencies all met for <TaskInstance: d_1_etl_FinalProject.get_data_from_api scheduled__2023-11-26T00:00:00+00:00 [queued]>
[2023-11-27 14:22:21,360] {taskinstance.py:1159} INFO - Dependencies all met for <TaskInstance: d_1_etl_FinalProject.get_data_from_api scheduled__2023-11-26T00:00:00+00:00 [queued]>
[2023-11-27 14:22:21,360] {taskinstance.py:1356} INFO - 
--------------------------------------------------------------------------------
[2023-11-27 14:22:21,361] {taskinstance.py:1357} INFO - Starting attempt 2 of 2
[2023-11-27 14:22:21,362] {taskinstance.py:1358} INFO - 
--------------------------------------------------------------------------------
[2023-11-27 14:22:21,383] {taskinstance.py:1377} INFO - Executing <Task(PythonOperator): get_data_from_api> on 2023-11-26 00:00:00+00:00
[2023-11-27 14:22:21,391] {standard_task_runner.py:52} INFO - Started process 2644 to run task
[2023-11-27 14:22:21,394] {standard_task_runner.py:79} INFO - Running: ['***', 'tasks', 'run', 'd_1_etl_FinalProject', 'get_data_from_api', 'scheduled__2023-11-26T00:00:00+00:00', '--job-id', '55', '--raw', '--subdir', 'DAGS_FOLDER/d_1_etl_FinalProject.py', '--cfg-path', '/tmp/tmpgpducyv2', '--error-file', '/tmp/tmp9kv4nj27']
[2023-11-27 14:22:21,395] {standard_task_runner.py:80} INFO - Job 55: Subtask get_data_from_api
[2023-11-27 14:22:21,469] {task_command.py:369} INFO - Running <TaskInstance: d_1_etl_FinalProject.get_data_from_api scheduled__2023-11-26T00:00:00+00:00 [running]> on host 92ab6769debf
[2023-11-27 14:22:21,556] {taskinstance.py:1571} INFO - Exporting the following env vars:
AIRFLOW_CTX_DAG_OWNER=***
AIRFLOW_CTX_DAG_ID=d_1_etl_FinalProject
AIRFLOW_CTX_TASK_ID=get_data_from_api
AIRFLOW_CTX_EXECUTION_DATE=2023-11-26T00:00:00+00:00
AIRFLOW_CTX_TRY_NUMBER=2
AIRFLOW_CTX_DAG_RUN_ID=scheduled__2023-11-26T00:00:00+00:00
[2023-11-27 14:22:21,665] {taskinstance.py:1889} ERROR - Task failed with exception
Traceback (most recent call last):
  File "/home/airflow/.local/lib/python3.7/site-packages/mysql/connector/connection_cext.py", line 246, in _open_connection
    self._cmysql.connect(**cnx_kwargs)
_mysql_connector.MySQLInterfaceError: Host 'host.docker.internal' is not allowed to connect to this MySQL server

During handling of the above exception, another exception occurred:

Traceback (most recent call last):
  File "/home/airflow/.local/lib/python3.7/site-packages/sqlalchemy/engine/base.py", line 3141, in _wrap_pool_connect
    return fn()
  File "/home/airflow/.local/lib/python3.7/site-packages/sqlalchemy/pool/base.py", line 301, in connect
    return _ConnectionFairy._checkout(self)
  File "/home/airflow/.local/lib/python3.7/site-packages/sqlalchemy/pool/base.py", line 755, in _checkout
    fairy = _ConnectionRecord.checkout(pool)
  File "/home/airflow/.local/lib/python3.7/site-packages/sqlalchemy/pool/base.py", line 419, in checkout
    rec = pool._do_get()
  File "/home/airflow/.local/lib/python3.7/site-packages/sqlalchemy/pool/impl.py", line 145, in _do_get
    self._dec_overflow()
  File "/home/airflow/.local/lib/python3.7/site-packages/sqlalchemy/util/langhelpers.py", line 72, in __exit__
    with_traceback=exc_tb,
  File "/home/airflow/.local/lib/python3.7/site-packages/sqlalchemy/util/compat.py", line 211, in raise_
    raise exception
  File "/home/airflow/.local/lib/python3.7/site-packages/sqlalchemy/pool/impl.py", line 142, in _do_get
    return self._create_connection()
  File "/home/airflow/.local/lib/python3.7/site-packages/sqlalchemy/pool/base.py", line 247, in _create_connection
    return _ConnectionRecord(self)
  File "/home/airflow/.local/lib/python3.7/site-packages/sqlalchemy/pool/base.py", line 362, in __init__
    self.__connect(first_connect_check=True)
  File "/home/airflow/.local/lib/python3.7/site-packages/sqlalchemy/pool/base.py", line 605, in __connect
    pool.logger.debug("Error on connect(): %s", e)
  File "/home/airflow/.local/lib/python3.7/site-packages/sqlalchemy/util/langhelpers.py", line 72, in __exit__
    with_traceback=exc_tb,
  File "/home/airflow/.local/lib/python3.7/site-packages/sqlalchemy/util/compat.py", line 211, in raise_
    raise exception
  File "/home/airflow/.local/lib/python3.7/site-packages/sqlalchemy/pool/base.py", line 599, in __connect
    connection = pool._invoke_creator(self)
  File "/home/airflow/.local/lib/python3.7/site-packages/sqlalchemy/engine/create.py", line 578, in connect
    return dialect.connect(*cargs, **cparams)
  File "/home/airflow/.local/lib/python3.7/site-packages/sqlalchemy/engine/default.py", line 583, in connect
    return self.dbapi.connect(*cargs, **cparams)
  File "/home/airflow/.local/lib/python3.7/site-packages/mysql/connector/__init__.py", line 272, in connect
    return CMySQLConnection(*args, **kwargs)
  File "/home/airflow/.local/lib/python3.7/site-packages/mysql/connector/connection_cext.py", line 94, in __init__
    self.connect(**kwargs)
  File "/home/airflow/.local/lib/python3.7/site-packages/mysql/connector/abstracts.py", line 1052, in connect
    self._open_connection()
  File "/home/airflow/.local/lib/python3.7/site-packages/mysql/connector/connection_cext.py", line 252, in _open_connection
    sqlstate=exc.sqlstate)
mysql.connector.errors.DatabaseError: 1130 (HY000): Host 'host.docker.internal' is not allowed to connect to this MySQL server

The above exception was the direct cause of the following exception:

Traceback (most recent call last):
  File "/home/airflow/.local/lib/python3.7/site-packages/airflow/operators/python.py", line 171, in execute
    return_value = self.execute_callable()
  File "/home/airflow/.local/lib/python3.7/site-packages/airflow/operators/python.py", line 189, in execute_callable
    return self.python_callable(*self.op_args, **self.op_kwargs)
  File "/opt/airflow/dags/d_1_etl_FinalProject.py", line 12, in get_data_from_api_func
    get_data_from_api_script.get_data_from_api()
  File "/opt/airflow/dags/modules/get_data_from_api_script.py", line 29, in get_data_from_api
    df.to_sql(mysql_table, con=engine, if_exists='replace', index=False)
  File "/home/airflow/.local/lib/python3.7/site-packages/pandas/core/generic.py", line 2882, in to_sql
    method=method,
  File "/home/airflow/.local/lib/python3.7/site-packages/pandas/io/sql.py", line 728, in to_sql
    **engine_kwargs,
  File "/home/airflow/.local/lib/python3.7/site-packages/pandas/io/sql.py", line 1758, in to_sql
    dtype=dtype,
  File "/home/airflow/.local/lib/python3.7/site-packages/pandas/io/sql.py", line 1650, in prep_table
    table.create()
  File "/home/airflow/.local/lib/python3.7/site-packages/pandas/io/sql.py", line 856, in create
    if self.exists():
  File "/home/airflow/.local/lib/python3.7/site-packages/pandas/io/sql.py", line 840, in exists
    return self.pd_sql.has_table(self.name, self.schema)
  File "/home/airflow/.local/lib/python3.7/site-packages/pandas/io/sql.py", line 1783, in has_table
    insp = sa.inspect(self.connectable)
  File "/home/airflow/.local/lib/python3.7/site-packages/sqlalchemy/inspection.py", line 64, in inspect
    ret = reg(subject)
  File "/home/airflow/.local/lib/python3.7/site-packages/sqlalchemy/engine/reflection.py", line 182, in _engine_insp
    return Inspector._construct(Inspector._init_engine, bind)
  File "/home/airflow/.local/lib/python3.7/site-packages/sqlalchemy/engine/reflection.py", line 117, in _construct
    init(self, bind)
  File "/home/airflow/.local/lib/python3.7/site-packages/sqlalchemy/engine/reflection.py", line 128, in _init_engine
    engine.connect().close()
  File "/home/airflow/.local/lib/python3.7/site-packages/sqlalchemy/engine/base.py", line 3095, in connect
    return self._connection_cls(self, close_with_result=close_with_result)
  File "/home/airflow/.local/lib/python3.7/site-packages/sqlalchemy/engine/base.py", line 91, in __init__
    else engine.raw_connection()
  File "/home/airflow/.local/lib/python3.7/site-packages/sqlalchemy/engine/base.py", line 3174, in raw_connection
    return self._wrap_pool_connect(self.pool.connect, _connection)
  File "/home/airflow/.local/lib/python3.7/site-packages/sqlalchemy/engine/base.py", line 3145, in _wrap_pool_connect
    e, dialect, self
  File "/home/airflow/.local/lib/python3.7/site-packages/sqlalchemy/engine/base.py", line 2004, in _handle_dbapi_exception_noconnection
    sqlalchemy_exception, with_traceback=exc_info[2], from_=e
  File "/home/airflow/.local/lib/python3.7/site-packages/sqlalchemy/util/compat.py", line 211, in raise_
    raise exception
  File "/home/airflow/.local/lib/python3.7/site-packages/sqlalchemy/engine/base.py", line 3141, in _wrap_pool_connect
    return fn()
  File "/home/airflow/.local/lib/python3.7/site-packages/sqlalchemy/pool/base.py", line 301, in connect
    return _ConnectionFairy._checkout(self)
  File "/home/airflow/.local/lib/python3.7/site-packages/sqlalchemy/pool/base.py", line 755, in _checkout
    fairy = _ConnectionRecord.checkout(pool)
  File "/home/airflow/.local/lib/python3.7/site-packages/sqlalchemy/pool/base.py", line 419, in checkout
    rec = pool._do_get()
  File "/home/airflow/.local/lib/python3.7/site-packages/sqlalchemy/pool/impl.py", line 145, in _do_get
    self._dec_overflow()
  File "/home/airflow/.local/lib/python3.7/site-packages/sqlalchemy/util/langhelpers.py", line 72, in __exit__
    with_traceback=exc_tb,
  File "/home/airflow/.local/lib/python3.7/site-packages/sqlalchemy/util/compat.py", line 211, in raise_
    raise exception
  File "/home/airflow/.local/lib/python3.7/site-packages/sqlalchemy/pool/impl.py", line 142, in _do_get
    return self._create_connection()
  File "/home/airflow/.local/lib/python3.7/site-packages/sqlalchemy/pool/base.py", line 247, in _create_connection
    return _ConnectionRecord(self)
  File "/home/airflow/.local/lib/python3.7/site-packages/sqlalchemy/pool/base.py", line 362, in __init__
    self.__connect(first_connect_check=True)
  File "/home/airflow/.local/lib/python3.7/site-packages/sqlalchemy/pool/base.py", line 605, in __connect
    pool.logger.debug("Error on connect(): %s", e)
  File "/home/airflow/.local/lib/python3.7/site-packages/sqlalchemy/util/langhelpers.py", line 72, in __exit__
    with_traceback=exc_tb,
  File "/home/airflow/.local/lib/python3.7/site-packages/sqlalchemy/util/compat.py", line 211, in raise_
    raise exception
  File "/home/airflow/.local/lib/python3.7/site-packages/sqlalchemy/pool/base.py", line 599, in __connect
    connection = pool._invoke_creator(self)
  File "/home/airflow/.local/lib/python3.7/site-packages/sqlalchemy/engine/create.py", line 578, in connect
    return dialect.connect(*cargs, **cparams)
  File "/home/airflow/.local/lib/python3.7/site-packages/sqlalchemy/engine/default.py", line 583, in connect
    return self.dbapi.connect(*cargs, **cparams)
  File "/home/airflow/.local/lib/python3.7/site-packages/mysql/connector/__init__.py", line 272, in connect
    return CMySQLConnection(*args, **kwargs)
  File "/home/airflow/.local/lib/python3.7/site-packages/mysql/connector/connection_cext.py", line 94, in __init__
    self.connect(**kwargs)
  File "/home/airflow/.local/lib/python3.7/site-packages/mysql/connector/abstracts.py", line 1052, in connect
    self._open_connection()
  File "/home/airflow/.local/lib/python3.7/site-packages/mysql/connector/connection_cext.py", line 252, in _open_connection
    sqlstate=exc.sqlstate)
sqlalchemy.exc.DatabaseError: (mysql.connector.errors.DatabaseError) 1130 (HY000): Host 'host.docker.internal' is not allowed to connect to this MySQL server
(Background on this error at: http://sqlalche.me/e/14/4xp6)
[2023-11-27 14:22:21,691] {taskinstance.py:1400} INFO - Marking task as FAILED. dag_id=d_1_etl_FinalProject, task_id=get_data_from_api, execution_date=20231126T000000, start_date=20231127T142221, end_date=20231127T142221
[2023-11-27 14:22:21,707] {standard_task_runner.py:97} ERROR - Failed to execute job 55 for task get_data_from_api ((mysql.connector.errors.DatabaseError) 1130 (HY000): Host 'host.docker.internal' is not allowed to connect to this MySQL server
(Background on this error at: http://sqlalche.me/e/14/4xp6); 2644)
[2023-11-27 14:22:21,729] {local_task_job.py:156} INFO - Task exited with return code 1
[2023-11-27 14:22:21,789] {local_task_job.py:273} INFO - 0 downstream tasks scheduled from follow-on schedule check
