[2023-11-28 10:20:17,181] {taskinstance.py:1159} INFO - Dependencies all met for <TaskInstance: d_1_etl_FinalProject.generate_dim manual__2023-11-27T14:17:35.380197+00:00 [queued]>
[2023-11-28 10:20:17,194] {taskinstance.py:1159} INFO - Dependencies all met for <TaskInstance: d_1_etl_FinalProject.generate_dim manual__2023-11-27T14:17:35.380197+00:00 [queued]>
[2023-11-28 10:20:17,195] {taskinstance.py:1356} INFO - 
--------------------------------------------------------------------------------
[2023-11-28 10:20:17,196] {taskinstance.py:1357} INFO - Starting attempt 5 of 5
[2023-11-28 10:20:17,197] {taskinstance.py:1358} INFO - 
--------------------------------------------------------------------------------
[2023-11-28 10:20:17,217] {taskinstance.py:1377} INFO - Executing <Task(PythonOperator): generate_dim> on 2023-11-27 14:17:35.380197+00:00
[2023-11-28 10:20:17,239] {standard_task_runner.py:79} INFO - Running: ['***', 'tasks', 'run', 'd_1_etl_FinalProject', 'generate_dim', 'manual__2023-11-27T14:17:35.380197+00:00', '--job-id', '73', '--raw', '--subdir', 'DAGS_FOLDER/d_1_etl_FinalProject.py', '--cfg-path', '/tmp/tmpzegzvda6', '--error-file', '/tmp/tmpebk82tlu']
[2023-11-28 10:20:17,232] {standard_task_runner.py:52} INFO - Started process 3015 to run task
[2023-11-28 10:20:17,242] {standard_task_runner.py:80} INFO - Job 73: Subtask generate_dim
[2023-11-28 10:20:17,335] {task_command.py:369} INFO - Running <TaskInstance: d_1_etl_FinalProject.generate_dim manual__2023-11-27T14:17:35.380197+00:00 [running]> on host 92ab6769debf
[2023-11-28 10:20:17,421] {taskinstance.py:1571} INFO - Exporting the following env vars:
AIRFLOW_CTX_DAG_OWNER=***
AIRFLOW_CTX_DAG_ID=d_1_etl_FinalProject
AIRFLOW_CTX_TASK_ID=generate_dim
AIRFLOW_CTX_EXECUTION_DATE=2023-11-27T14:17:35.380197+00:00
AIRFLOW_CTX_TRY_NUMBER=5
AIRFLOW_CTX_DAG_RUN_ID=manual__2023-11-27T14:17:35.380197+00:00
[2023-11-28 10:20:17,423] {taskinstance.py:1889} ERROR - Task failed with exception
Traceback (most recent call last):
  File "/home/airflow/.local/lib/python3.7/site-packages/airflow/operators/python.py", line 171, in execute
    return_value = self.execute_callable()
  File "/home/airflow/.local/lib/python3.7/site-packages/airflow/operators/python.py", line 189, in execute_callable
    return self.python_callable(*self.op_args, **self.op_kwargs)
  File "/opt/airflow/dags/d_1_etl_FinalProject.py", line 11, in generate_dim_func
    generate_dim_script.load_dimension_table()
AttributeError: module 'modules.generate_dim_script' has no attribute 'load_dimension_table'
[2023-11-28 10:20:17,444] {taskinstance.py:1400} INFO - Marking task as FAILED. dag_id=d_1_etl_FinalProject, task_id=generate_dim, execution_date=20231127T141735, start_date=20231128T102017, end_date=20231128T102017
[2023-11-28 10:20:17,459] {standard_task_runner.py:97} ERROR - Failed to execute job 73 for task generate_dim (module 'modules.generate_dim_script' has no attribute 'load_dimension_table'; 3015)
[2023-11-28 10:20:17,503] {local_task_job.py:156} INFO - Task exited with return code 1
[2023-11-28 10:20:17,543] {local_task_job.py:273} INFO - 0 downstream tasks scheduled from follow-on schedule check
