[2023-11-28 16:31:46,307] {taskinstance.py:1159} INFO - Dependencies all met for <TaskInstance: d_1_etl_FinalProject.generate_dim manual__2023-11-27T14:17:35.380197+00:00 [queued]>
[2023-11-28 16:31:46,340] {taskinstance.py:1159} INFO - Dependencies all met for <TaskInstance: d_1_etl_FinalProject.generate_dim manual__2023-11-27T14:17:35.380197+00:00 [queued]>
[2023-11-28 16:31:46,341] {taskinstance.py:1356} INFO - 
--------------------------------------------------------------------------------
[2023-11-28 16:31:46,341] {taskinstance.py:1357} INFO - Starting attempt 13 of 13
[2023-11-28 16:31:46,342] {taskinstance.py:1358} INFO - 
--------------------------------------------------------------------------------
[2023-11-28 16:31:46,380] {taskinstance.py:1377} INFO - Executing <Task(PythonOperator): generate_dim> on 2023-11-27 14:17:35.380197+00:00
[2023-11-28 16:31:46,393] {standard_task_runner.py:52} INFO - Started process 14666 to run task
[2023-11-28 16:31:46,476] {standard_task_runner.py:79} INFO - Running: ['***', 'tasks', 'run', 'd_1_etl_FinalProject', 'generate_dim', 'manual__2023-11-27T14:17:35.380197+00:00', '--job-id', '81', '--raw', '--subdir', 'DAGS_FOLDER/d_1_etl_FinalProject.py', '--cfg-path', '/tmp/tmp9pp88mjh', '--error-file', '/tmp/tmpdukea280']
[2023-11-28 16:31:46,477] {standard_task_runner.py:80} INFO - Job 81: Subtask generate_dim
[2023-11-28 16:31:46,652] {task_command.py:369} INFO - Running <TaskInstance: d_1_etl_FinalProject.generate_dim manual__2023-11-27T14:17:35.380197+00:00 [running]> on host 92ab6769debf
[2023-11-28 16:31:46,801] {taskinstance.py:1571} INFO - Exporting the following env vars:
AIRFLOW_CTX_DAG_OWNER=***
AIRFLOW_CTX_DAG_ID=d_1_etl_FinalProject
AIRFLOW_CTX_TASK_ID=generate_dim
AIRFLOW_CTX_EXECUTION_DATE=2023-11-27T14:17:35.380197+00:00
AIRFLOW_CTX_TRY_NUMBER=13
AIRFLOW_CTX_DAG_RUN_ID=manual__2023-11-27T14:17:35.380197+00:00
[2023-11-28 16:31:47,337] {taskinstance.py:1889} ERROR - Task failed with exception
Traceback (most recent call last):
  File "/home/airflow/.local/lib/python3.7/site-packages/airflow/operators/python.py", line 171, in execute
    return_value = self.execute_callable()
  File "/home/airflow/.local/lib/python3.7/site-packages/airflow/operators/python.py", line 189, in execute_callable
    return self.python_callable(*self.op_args, **self.op_kwargs)
  File "/opt/airflow/dags/d_1_etl_FinalProject.py", line 11, in generate_dim_func
    generate_dim_script.load_dimension_tables(**kwargs)
  File "/opt/airflow/dags/modules/generate_dim_script.py", line 36, in load_dimension_tables
    ti.xcom_push(key='dim_province_data', value=load_dim_province(mysql_conn, postgres_conn))
  File "/opt/airflow/dags/modules/generate_dim_script.py", line 57, in load_dim_province
    (row['kode_prov'], row['nama_prov']))
psycopg2.errors.UniqueViolation: duplicate key value violates unique constraint "dim_province_pkey"
DETAIL:  Key (province_id)=(32) already exists.

[2023-11-28 16:31:47,377] {taskinstance.py:1400} INFO - Marking task as FAILED. dag_id=d_1_etl_FinalProject, task_id=generate_dim, execution_date=20231127T141735, start_date=20231128T163146, end_date=20231128T163147
[2023-11-28 16:31:47,404] {standard_task_runner.py:97} ERROR - Failed to execute job 81 for task generate_dim (duplicate key value violates unique constraint "dim_province_pkey"
DETAIL:  Key (province_id)=(32) already exists.
; 14666)
[2023-11-28 16:31:47,462] {local_task_job.py:156} INFO - Task exited with return code 1
[2023-11-28 16:31:47,553] {local_task_job.py:273} INFO - 0 downstream tasks scheduled from follow-on schedule check
