[2023-11-28 15:00:51,921] {taskinstance.py:1159} INFO - Dependencies all met for <TaskInstance: d_1_etl_FinalProject.generate_dim manual__2023-11-27T14:17:35.380197+00:00 [queued]>
[2023-11-28 15:00:51,933] {taskinstance.py:1159} INFO - Dependencies all met for <TaskInstance: d_1_etl_FinalProject.generate_dim manual__2023-11-27T14:17:35.380197+00:00 [queued]>
[2023-11-28 15:00:51,934] {taskinstance.py:1356} INFO - 
--------------------------------------------------------------------------------
[2023-11-28 15:00:51,935] {taskinstance.py:1357} INFO - Starting attempt 9 of 9
[2023-11-28 15:00:51,936] {taskinstance.py:1358} INFO - 
--------------------------------------------------------------------------------
[2023-11-28 15:00:51,954] {taskinstance.py:1377} INFO - Executing <Task(PythonOperator): generate_dim> on 2023-11-27 14:17:35.380197+00:00
[2023-11-28 15:00:51,985] {standard_task_runner.py:52} INFO - Started process 11797 to run task
[2023-11-28 15:00:51,989] {standard_task_runner.py:79} INFO - Running: ['***', 'tasks', 'run', 'd_1_etl_FinalProject', 'generate_dim', 'manual__2023-11-27T14:17:35.380197+00:00', '--job-id', '77', '--raw', '--subdir', 'DAGS_FOLDER/d_1_etl_FinalProject.py', '--cfg-path', '/tmp/tmpyyfcd_2t', '--error-file', '/tmp/tmpkos76poz']
[2023-11-28 15:00:51,990] {standard_task_runner.py:80} INFO - Job 77: Subtask generate_dim
[2023-11-28 15:00:52,072] {task_command.py:369} INFO - Running <TaskInstance: d_1_etl_FinalProject.generate_dim manual__2023-11-27T14:17:35.380197+00:00 [running]> on host 92ab6769debf
[2023-11-28 15:00:52,168] {taskinstance.py:1571} INFO - Exporting the following env vars:
AIRFLOW_CTX_DAG_OWNER=***
AIRFLOW_CTX_DAG_ID=d_1_etl_FinalProject
AIRFLOW_CTX_TASK_ID=generate_dim
AIRFLOW_CTX_EXECUTION_DATE=2023-11-27T14:17:35.380197+00:00
AIRFLOW_CTX_TRY_NUMBER=9
AIRFLOW_CTX_DAG_RUN_ID=manual__2023-11-27T14:17:35.380197+00:00
[2023-11-28 15:00:52,216] {taskinstance.py:1889} ERROR - Task failed with exception
Traceback (most recent call last):
  File "/home/airflow/.local/lib/python3.7/site-packages/mysql/connector/connection_cext.py", line 246, in _open_connection
    self._cmysql.connect(**cnx_kwargs)
_mysql_connector.MySQLInterfaceError: Host 'host.docker.internal' is not allowed to connect to this MySQL server

During handling of the above exception, another exception occurred:

Traceback (most recent call last):
  File "/home/airflow/.local/lib/python3.7/site-packages/airflow/operators/python.py", line 171, in execute
    return_value = self.execute_callable()
  File "/home/airflow/.local/lib/python3.7/site-packages/airflow/operators/python.py", line 189, in execute_callable
    return self.python_callable(*self.op_args, **self.op_kwargs)
  File "/opt/airflow/dags/d_1_etl_FinalProject.py", line 11, in generate_dim_func
    generate_dim_script.load_dimension_tables(**kwargs)
  File "/opt/airflow/dags/modules/generate_dim_script.py", line 30, in load_dimension_tables
    mysql_conn = get_mysql_connection()
  File "/opt/airflow/dags/modules/generate_dim_script.py", line 15, in get_mysql_connection
    database='mysql'
  File "/home/airflow/.local/lib/python3.7/site-packages/mysql/connector/__init__.py", line 272, in connect
    return CMySQLConnection(*args, **kwargs)
  File "/home/airflow/.local/lib/python3.7/site-packages/mysql/connector/connection_cext.py", line 94, in __init__
    self.connect(**kwargs)
  File "/home/airflow/.local/lib/python3.7/site-packages/mysql/connector/abstracts.py", line 1052, in connect
    self._open_connection()
  File "/home/airflow/.local/lib/python3.7/site-packages/mysql/connector/connection_cext.py", line 252, in _open_connection
    sqlstate=exc.sqlstate)
mysql.connector.errors.DatabaseError: 1130 (HY000): Host 'host.docker.internal' is not allowed to connect to this MySQL server
[2023-11-28 15:00:52,240] {taskinstance.py:1400} INFO - Marking task as FAILED. dag_id=d_1_etl_FinalProject, task_id=generate_dim, execution_date=20231127T141735, start_date=20231128T150051, end_date=20231128T150052
[2023-11-28 15:00:52,257] {standard_task_runner.py:97} ERROR - Failed to execute job 77 for task generate_dim (1130 (HY000): Host 'host.docker.internal' is not allowed to connect to this MySQL server; 11797)
[2023-11-28 15:00:52,282] {local_task_job.py:156} INFO - Task exited with return code 1
[2023-11-28 15:00:52,328] {local_task_job.py:273} INFO - 0 downstream tasks scheduled from follow-on schedule check
