[2023-11-28 15:11:02,103] {taskinstance.py:1159} INFO - Dependencies all met for <TaskInstance: d_1_etl_FinalProject.generate_dim manual__2023-11-27T14:17:35.380197+00:00 [queued]>
[2023-11-28 15:11:02,114] {taskinstance.py:1159} INFO - Dependencies all met for <TaskInstance: d_1_etl_FinalProject.generate_dim manual__2023-11-27T14:17:35.380197+00:00 [queued]>
[2023-11-28 15:11:02,115] {taskinstance.py:1356} INFO - 
--------------------------------------------------------------------------------
[2023-11-28 15:11:02,116] {taskinstance.py:1357} INFO - Starting attempt 11 of 11
[2023-11-28 15:11:02,117] {taskinstance.py:1358} INFO - 
--------------------------------------------------------------------------------
[2023-11-28 15:11:02,138] {taskinstance.py:1377} INFO - Executing <Task(PythonOperator): generate_dim> on 2023-11-27 14:17:35.380197+00:00
[2023-11-28 15:11:02,172] {standard_task_runner.py:52} INFO - Started process 12143 to run task
[2023-11-28 15:11:02,175] {standard_task_runner.py:79} INFO - Running: ['***', 'tasks', 'run', 'd_1_etl_FinalProject', 'generate_dim', 'manual__2023-11-27T14:17:35.380197+00:00', '--job-id', '79', '--raw', '--subdir', 'DAGS_FOLDER/d_1_etl_FinalProject.py', '--cfg-path', '/tmp/tmpbj25vr65', '--error-file', '/tmp/tmpkyawev4t']
[2023-11-28 15:11:02,176] {standard_task_runner.py:80} INFO - Job 79: Subtask generate_dim
[2023-11-28 15:11:02,262] {task_command.py:369} INFO - Running <TaskInstance: d_1_etl_FinalProject.generate_dim manual__2023-11-27T14:17:35.380197+00:00 [running]> on host 92ab6769debf
[2023-11-28 15:11:02,386] {taskinstance.py:1571} INFO - Exporting the following env vars:
AIRFLOW_CTX_DAG_OWNER=***
AIRFLOW_CTX_DAG_ID=d_1_etl_FinalProject
AIRFLOW_CTX_TASK_ID=generate_dim
AIRFLOW_CTX_EXECUTION_DATE=2023-11-27T14:17:35.380197+00:00
AIRFLOW_CTX_TRY_NUMBER=11
AIRFLOW_CTX_DAG_RUN_ID=manual__2023-11-27T14:17:35.380197+00:00
[2023-11-28 15:11:02,843] {taskinstance.py:1889} ERROR - Task failed with exception
Traceback (most recent call last):
  File "/home/airflow/.local/lib/python3.7/site-packages/mysql/connector/connection_cext.py", line 538, in cmd_query
    query_attrs=self._query_attrs)
_mysql_connector.MySQLInterfaceError: Unknown column 'province_id' in 'field list'

During handling of the above exception, another exception occurred:

Traceback (most recent call last):
  File "/home/airflow/.local/lib/python3.7/site-packages/airflow/operators/python.py", line 171, in execute
    return_value = self.execute_callable()
  File "/home/airflow/.local/lib/python3.7/site-packages/airflow/operators/python.py", line 189, in execute_callable
    return self.python_callable(*self.op_args, **self.op_kwargs)
  File "/opt/airflow/dags/d_1_etl_FinalProject.py", line 11, in generate_dim_func
    generate_dim_script.load_dimension_tables(**kwargs)
  File "/opt/airflow/dags/modules/generate_dim_script.py", line 36, in load_dimension_tables
    ti.xcom_push(key='dim_province_data', value=load_dim_province(mysql_conn, postgres_conn))
  File "/opt/airflow/dags/modules/generate_dim_script.py", line 51, in load_dim_province
    cursor_mysql.execute('SELECT province_id, province_name FROM covid_jabar')
  File "/home/airflow/.local/lib/python3.7/site-packages/mysql/connector/cursor_cext.py", line 271, in execute
    raw_as_string=self._raw_as_string)
  File "/home/airflow/.local/lib/python3.7/site-packages/mysql/connector/connection_cext.py", line 541, in cmd_query
    sqlstate=exc.sqlstate)
mysql.connector.errors.ProgrammingError: 1054 (42S22): Unknown column 'province_id' in 'field list'
[2023-11-28 15:11:02,875] {taskinstance.py:1400} INFO - Marking task as FAILED. dag_id=d_1_etl_FinalProject, task_id=generate_dim, execution_date=20231127T141735, start_date=20231128T151102, end_date=20231128T151102
[2023-11-28 15:11:02,894] {standard_task_runner.py:97} ERROR - Failed to execute job 79 for task generate_dim (1054 (42S22): Unknown column 'province_id' in 'field list'; 12143)
[2023-11-28 15:11:02,918] {local_task_job.py:156} INFO - Task exited with return code 1
[2023-11-28 15:11:02,965] {local_task_job.py:273} INFO - 0 downstream tasks scheduled from follow-on schedule check
