[2023-11-28 16:26:54,644] {taskinstance.py:1159} INFO - Dependencies all met for <TaskInstance: d_1_etl_FinalProject.generate_dim manual__2023-11-27T14:17:35.380197+00:00 [queued]>
[2023-11-28 16:26:54,658] {taskinstance.py:1159} INFO - Dependencies all met for <TaskInstance: d_1_etl_FinalProject.generate_dim manual__2023-11-27T14:17:35.380197+00:00 [queued]>
[2023-11-28 16:26:54,659] {taskinstance.py:1356} INFO - 
--------------------------------------------------------------------------------
[2023-11-28 16:26:54,659] {taskinstance.py:1357} INFO - Starting attempt 12 of 12
[2023-11-28 16:26:54,660] {taskinstance.py:1358} INFO - 
--------------------------------------------------------------------------------
[2023-11-28 16:26:54,676] {taskinstance.py:1377} INFO - Executing <Task(PythonOperator): generate_dim> on 2023-11-27 14:17:35.380197+00:00
[2023-11-28 16:26:54,695] {standard_task_runner.py:52} INFO - Started process 14509 to run task
[2023-11-28 16:26:54,701] {standard_task_runner.py:79} INFO - Running: ['***', 'tasks', 'run', 'd_1_etl_FinalProject', 'generate_dim', 'manual__2023-11-27T14:17:35.380197+00:00', '--job-id', '80', '--raw', '--subdir', 'DAGS_FOLDER/d_1_etl_FinalProject.py', '--cfg-path', '/tmp/tmp64swt6p3', '--error-file', '/tmp/tmp4962ep27']
[2023-11-28 16:26:54,702] {standard_task_runner.py:80} INFO - Job 80: Subtask generate_dim
[2023-11-28 16:26:54,789] {task_command.py:369} INFO - Running <TaskInstance: d_1_etl_FinalProject.generate_dim manual__2023-11-27T14:17:35.380197+00:00 [running]> on host 92ab6769debf
[2023-11-28 16:26:54,886] {taskinstance.py:1571} INFO - Exporting the following env vars:
AIRFLOW_CTX_DAG_OWNER=***
AIRFLOW_CTX_DAG_ID=d_1_etl_FinalProject
AIRFLOW_CTX_TASK_ID=generate_dim
AIRFLOW_CTX_EXECUTION_DATE=2023-11-27T14:17:35.380197+00:00
AIRFLOW_CTX_TRY_NUMBER=12
AIRFLOW_CTX_DAG_RUN_ID=manual__2023-11-27T14:17:35.380197+00:00
[2023-11-28 16:26:55,234] {taskinstance.py:1889} ERROR - Task failed with exception
Traceback (most recent call last):
  File "/home/airflow/.local/lib/python3.7/site-packages/airflow/operators/python.py", line 171, in execute
    return_value = self.execute_callable()
  File "/home/airflow/.local/lib/python3.7/site-packages/airflow/operators/python.py", line 189, in execute_callable
    return self.python_callable(*self.op_args, **self.op_kwargs)
  File "/opt/airflow/dags/d_1_etl_FinalProject.py", line 11, in generate_dim_func
    generate_dim_script.load_dimension_tables(**kwargs)
  File "/opt/airflow/dags/modules/generate_dim_script.py", line 36, in load_dimension_tables
    ti.xcom_push(key='dim_province_data', value=load_dim_province(mysql_conn, postgres_conn))
  File "/opt/airflow/dags/modules/generate_dim_script.py", line 57, in load_dim_province
    (row['province_id'], row['province_name']))
KeyError: 'province_id'
[2023-11-28 16:26:55,256] {taskinstance.py:1400} INFO - Marking task as FAILED. dag_id=d_1_etl_FinalProject, task_id=generate_dim, execution_date=20231127T141735, start_date=20231128T162654, end_date=20231128T162655
[2023-11-28 16:26:55,275] {standard_task_runner.py:97} ERROR - Failed to execute job 80 for task generate_dim ('province_id'; 14509)
[2023-11-28 16:26:55,316] {local_task_job.py:156} INFO - Task exited with return code 1
[2023-11-28 16:26:55,372] {local_task_job.py:273} INFO - 0 downstream tasks scheduled from follow-on schedule check
