[2023-11-28 16:35:51,995] {taskinstance.py:1159} INFO - Dependencies all met for <TaskInstance: d_1_etl_FinalProject.generate_dim manual__2023-11-27T14:17:35.380197+00:00 [queued]>
[2023-11-28 16:35:52,014] {taskinstance.py:1159} INFO - Dependencies all met for <TaskInstance: d_1_etl_FinalProject.generate_dim manual__2023-11-27T14:17:35.380197+00:00 [queued]>
[2023-11-28 16:35:52,016] {taskinstance.py:1356} INFO - 
--------------------------------------------------------------------------------
[2023-11-28 16:35:52,017] {taskinstance.py:1357} INFO - Starting attempt 14 of 14
[2023-11-28 16:35:52,018] {taskinstance.py:1358} INFO - 
--------------------------------------------------------------------------------
[2023-11-28 16:35:52,044] {taskinstance.py:1377} INFO - Executing <Task(PythonOperator): generate_dim> on 2023-11-27 14:17:35.380197+00:00
[2023-11-28 16:35:52,065] {standard_task_runner.py:52} INFO - Started process 14812 to run task
[2023-11-28 16:35:52,093] {standard_task_runner.py:79} INFO - Running: ['***', 'tasks', 'run', 'd_1_etl_FinalProject', 'generate_dim', 'manual__2023-11-27T14:17:35.380197+00:00', '--job-id', '82', '--raw', '--subdir', 'DAGS_FOLDER/d_1_etl_FinalProject.py', '--cfg-path', '/tmp/tmp01lbtonc', '--error-file', '/tmp/tmp189hg84m']
[2023-11-28 16:35:52,095] {standard_task_runner.py:80} INFO - Job 82: Subtask generate_dim
[2023-11-28 16:35:52,323] {task_command.py:369} INFO - Running <TaskInstance: d_1_etl_FinalProject.generate_dim manual__2023-11-27T14:17:35.380197+00:00 [running]> on host 92ab6769debf
[2023-11-28 16:35:52,478] {taskinstance.py:1571} INFO - Exporting the following env vars:
AIRFLOW_CTX_DAG_OWNER=***
AIRFLOW_CTX_DAG_ID=d_1_etl_FinalProject
AIRFLOW_CTX_TASK_ID=generate_dim
AIRFLOW_CTX_EXECUTION_DATE=2023-11-27T14:17:35.380197+00:00
AIRFLOW_CTX_TRY_NUMBER=14
AIRFLOW_CTX_DAG_RUN_ID=manual__2023-11-27T14:17:35.380197+00:00
[2023-11-28 16:35:54,405] {taskinstance.py:1889} ERROR - Task failed with exception
Traceback (most recent call last):
  File "/home/airflow/.local/lib/python3.7/site-packages/airflow/operators/python.py", line 171, in execute
    return_value = self.execute_callable()
  File "/home/airflow/.local/lib/python3.7/site-packages/airflow/operators/python.py", line 189, in execute_callable
    return self.python_callable(*self.op_args, **self.op_kwargs)
  File "/opt/airflow/dags/d_1_etl_FinalProject.py", line 11, in generate_dim_func
    generate_dim_script.load_dimension_tables(**kwargs)
  File "/opt/airflow/dags/modules/generate_dim_script.py", line 42, in load_dimension_tables
    ti.xcom_push(key='dim_case_data', value=load_dim_case(mysql_conn, postgres_conn))
NameError: name 'load_dim_case' is not defined
[2023-11-28 16:35:54,481] {taskinstance.py:1400} INFO - Marking task as FAILED. dag_id=d_1_etl_FinalProject, task_id=generate_dim, execution_date=20231127T141735, start_date=20231128T163551, end_date=20231128T163554
[2023-11-28 16:35:54,506] {standard_task_runner.py:97} ERROR - Failed to execute job 82 for task generate_dim (name 'load_dim_case' is not defined; 14812)
[2023-11-28 16:35:54,533] {local_task_job.py:156} INFO - Task exited with return code 1
[2023-11-28 16:35:54,625] {local_task_job.py:273} INFO - 0 downstream tasks scheduled from follow-on schedule check
